Internal Server Error: /api/contracts/
Traceback (most recent call last):
  File "C:\Users\charl\Documents\GitHub\p12_v2\env\lib\site-packages\django\core\handlers\exception.py", line 55, in inner
    response = get_response(request)
  File "C:\Users\charl\Documents\GitHub\p12_v2\env\lib\site-packages\django\core\handlers\base.py", line 197, in _get_response
    response = wrapped_callback(request, *callback_args, **callback_kwargs)
  File "C:\Users\charl\Documents\GitHub\p12_v2\env\lib\site-packages\django\views\decorators\csrf.py", line 54, in wrapped_view
    return view_func(*args, **kwargs)
  File "C:\Users\charl\Documents\GitHub\p12_v2\env\lib\site-packages\rest_framework\viewsets.py", line 125, in view
    return self.dispatch(request, *args, **kwargs)
  File "C:\Users\charl\Documents\GitHub\p12_v2\env\lib\site-packages\rest_framework\views.py", line 509, in dispatch
    response = self.handle_exception(exc)
  File "C:\Users\charl\Documents\GitHub\p12_v2\env\lib\site-packages\rest_framework\views.py", line 469, in handle_exception
    self.raise_uncaught_exception(exc)
  File "C:\Users\charl\Documents\GitHub\p12_v2\env\lib\site-packages\rest_framework\views.py", line 480, in raise_uncaught_exception
    raise exc
  File "C:\Users\charl\Documents\GitHub\p12_v2\env\lib\site-packages\rest_framework\views.py", line 506, in dispatch
    response = handler(request, *args, **kwargs)
  File "C:\Users\charl\Documents\GitHub\p12_v2\env\lib\site-packages\rest_framework\mixins.py", line 38, in list
    queryset = self.filter_queryset(self.get_queryset())
  File "C:\Users\charl\Documents\GitHub\p12_v2\epicevents\app\views.py", line 116, in get_queryset
    queryset = Contract.objects.filter(event__contract__support_contact=self.request.user)
  File "C:\Users\charl\Documents\GitHub\p12_v2\env\lib\site-packages\django\db\models\manager.py", line 85, in manager_method
    return getattr(self.get_queryset(), name)(*args, **kwargs)
  File "C:\Users\charl\Documents\GitHub\p12_v2\env\lib\site-packages\django\db\models\query.py", line 1421, in filter
    return self._filter_or_exclude(False, args, kwargs)
  File "C:\Users\charl\Documents\GitHub\p12_v2\env\lib\site-packages\django\db\models\query.py", line 1439, in _filter_or_exclude
    clone._filter_or_exclude_inplace(negate, args, kwargs)
  File "C:\Users\charl\Documents\GitHub\p12_v2\env\lib\site-packages\django\db\models\query.py", line 1446, in _filter_or_exclude_inplace
    self._query.add_q(Q(*args, **kwargs))
  File "C:\Users\charl\Documents\GitHub\p12_v2\env\lib\site-packages\django\db\models\sql\query.py", line 1532, in add_q
    clause, _ = self._add_q(q_object, self.used_aliases)
  File "C:\Users\charl\Documents\GitHub\p12_v2\env\lib\site-packages\django\db\models\sql\query.py", line 1562, in _add_q
    child_clause, needed_inner = self.build_filter(
  File "C:\Users\charl\Documents\GitHub\p12_v2\env\lib\site-packages\django\db\models\sql\query.py", line 1445, in build_filter
    self.check_related_objects(join_info.final_field, value, join_info.opts)
  File "C:\Users\charl\Documents\GitHub\p12_v2\env\lib\site-packages\django\db\models\sql\query.py", line 1256, in check_related_objects
    self.check_query_object_type(value, opts, field)
  File "C:\Users\charl\Documents\GitHub\p12_v2\env\lib\site-packages\django\db\models\sql\query.py", line 1233, in check_query_object_type
    raise ValueError(
ValueError: Cannot query "Support_user": Must be "Contract" instance.
"GET /api/contracts/ HTTP/1.1" 500 145
Internal Server Error: /api/events/
Traceback (most recent call last):
  File "C:\Users\charl\Documents\GitHub\p12_v2\env\lib\site-packages\django\core\handlers\exception.py", line 55, in inner
    response = get_response(request)
  File "C:\Users\charl\Documents\GitHub\p12_v2\env\lib\site-packages\django\core\handlers\base.py", line 197, in _get_response
    response = wrapped_callback(request, *callback_args, **callback_kwargs)
  File "C:\Users\charl\Documents\GitHub\p12_v2\env\lib\site-packages\django\views\decorators\csrf.py", line 54, in wrapped_view
    return view_func(*args, **kwargs)
  File "C:\Users\charl\Documents\GitHub\p12_v2\env\lib\site-packages\rest_framework\viewsets.py", line 125, in view
    return self.dispatch(request, *args, **kwargs)
  File "C:\Users\charl\Documents\GitHub\p12_v2\env\lib\site-packages\rest_framework\views.py", line 509, in dispatch
    response = self.handle_exception(exc)
  File "C:\Users\charl\Documents\GitHub\p12_v2\env\lib\site-packages\rest_framework\views.py", line 469, in handle_exception
    self.raise_uncaught_exception(exc)
  File "C:\Users\charl\Documents\GitHub\p12_v2\env\lib\site-packages\rest_framework\views.py", line 480, in raise_uncaught_exception
    raise exc
  File "C:\Users\charl\Documents\GitHub\p12_v2\env\lib\site-packages\rest_framework\views.py", line 506, in dispatch
    response = handler(request, *args, **kwargs)
  File "C:\Users\charl\Documents\GitHub\p12_v2\env\lib\site-packages\rest_framework\mixins.py", line 38, in list
    queryset = self.filter_queryset(self.get_queryset())
  File "C:\Users\charl\Documents\GitHub\p12_v2\epicevents\app\views.py", line 173, in get_queryset
    raise PermissionError('You do not have permission')
PermissionError: You do not have permission
"GET /api/events/ HTTP/1.1" 500 145
Internal Server Error: /api/events/
Traceback (most recent call last):
  File "C:\Users\charl\Documents\GitHub\p12_v2\env\lib\site-packages\django\core\handlers\exception.py", line 55, in inner
    response = get_response(request)
  File "C:\Users\charl\Documents\GitHub\p12_v2\env\lib\site-packages\django\core\handlers\base.py", line 197, in _get_response
    response = wrapped_callback(request, *callback_args, **callback_kwargs)
  File "C:\Users\charl\Documents\GitHub\p12_v2\env\lib\site-packages\django\views\decorators\csrf.py", line 54, in wrapped_view
    return view_func(*args, **kwargs)
  File "C:\Users\charl\Documents\GitHub\p12_v2\env\lib\site-packages\rest_framework\viewsets.py", line 125, in view
    return self.dispatch(request, *args, **kwargs)
  File "C:\Users\charl\Documents\GitHub\p12_v2\env\lib\site-packages\rest_framework\views.py", line 509, in dispatch
    response = self.handle_exception(exc)
  File "C:\Users\charl\Documents\GitHub\p12_v2\env\lib\site-packages\rest_framework\views.py", line 469, in handle_exception
    self.raise_uncaught_exception(exc)
  File "C:\Users\charl\Documents\GitHub\p12_v2\env\lib\site-packages\rest_framework\views.py", line 480, in raise_uncaught_exception
    raise exc
  File "C:\Users\charl\Documents\GitHub\p12_v2\env\lib\site-packages\rest_framework\views.py", line 506, in dispatch
    response = handler(request, *args, **kwargs)
  File "C:\Users\charl\Documents\GitHub\p12_v2\env\lib\site-packages\rest_framework\mixins.py", line 38, in list
    queryset = self.filter_queryset(self.get_queryset())
  File "C:\Users\charl\Documents\GitHub\p12_v2\epicevents\app\views.py", line 173, in get_queryset
    raise PermissionError('You do not have permission')
PermissionError: You do not have permission
"GET /api/events/ HTTP/1.1" 500 145
